[2023-11-27T07:57:24.128+0000] {taskinstance.py:1159} INFO - Dependencies all met for dep_context=non-requeueable deps ti=<TaskInstance: ETL_Pipeline.extract_kalerkantho scheduled__2023-11-26T00:00:00+00:00 [queued]>
[2023-11-27T07:57:24.142+0000] {taskinstance.py:1159} INFO - Dependencies all met for dep_context=requeueable deps ti=<TaskInstance: ETL_Pipeline.extract_kalerkantho scheduled__2023-11-26T00:00:00+00:00 [queued]>
[2023-11-27T07:57:24.142+0000] {taskinstance.py:1361} INFO - Starting attempt 1 of 2
[2023-11-27T07:57:24.163+0000] {taskinstance.py:1382} INFO - Executing <Task(PythonOperator): extract_kalerkantho> on 2023-11-26 00:00:00+00:00
[2023-11-27T07:57:24.168+0000] {standard_task_runner.py:57} INFO - Started process 56 to run task
[2023-11-27T07:57:24.172+0000] {standard_task_runner.py:84} INFO - Running: ['***', 'tasks', 'run', 'ETL_Pipeline', 'extract_kalerkantho', 'scheduled__2023-11-26T00:00:00+00:00', '--job-id', '473', '--raw', '--subdir', 'DAGS_FOLDER/ETL_Pipeline.py', '--cfg-path', '/tmp/tmpd7dr_ob9']
[2023-11-27T07:57:24.175+0000] {standard_task_runner.py:85} INFO - Job 473: Subtask extract_kalerkantho
[2023-11-27T07:57:24.250+0000] {task_command.py:416} INFO - Running <TaskInstance: ETL_Pipeline.extract_kalerkantho scheduled__2023-11-26T00:00:00+00:00 [running]> on host 4012deabc79b
[2023-11-27T07:57:24.356+0000] {taskinstance.py:1662} INFO - Exporting env vars: AIRFLOW_CTX_DAG_OWNER='***' AIRFLOW_CTX_DAG_ID='ETL_Pipeline' AIRFLOW_CTX_TASK_ID='extract_kalerkantho' AIRFLOW_CTX_EXECUTION_DATE='2023-11-26T00:00:00+00:00' AIRFLOW_CTX_TRY_NUMBER='1' AIRFLOW_CTX_DAG_RUN_ID='scheduled__2023-11-26T00:00:00+00:00'
[2023-11-27T07:57:24.362+0000] {extract.py:22} ERROR - Could not fetch content due to error: HTTPSConnectionPool(host='www.kalerkantho.com', port=443): Max retries exceeded with url: /sitemap.xml (Caused by NewConnectionError('<urllib3.connection.HTTPSConnection object at 0x7f97d627ea30>: Failed to establish a new connection: [Errno -3] Temporary failure in name resolution'))
[2023-11-27T07:57:24.363+0000] {taskinstance.py:1937} ERROR - Task failed with exception
Traceback (most recent call last):
  File "/home/airflow/.local/lib/python3.8/site-packages/airflow/operators/python.py", line 192, in execute
    return_value = self.execute_callable()
  File "/home/airflow/.local/lib/python3.8/site-packages/airflow/operators/python.py", line 209, in execute_callable
    return self.python_callable(*self.op_args, **self.op_kwargs)
  File "/opt/airflow/dags/utils/extract.py", line 52, in parse_from_kalerkantho
    latest_news_sitemap = sitemap_soup.find_all("loc")[1].text
AttributeError: 'NoneType' object has no attribute 'find_all'
[2023-11-27T07:57:24.372+0000] {taskinstance.py:1400} INFO - Marking task as UP_FOR_RETRY. dag_id=ETL_Pipeline, task_id=extract_kalerkantho, execution_date=20231126T000000, start_date=20231127T075724, end_date=20231127T075724
[2023-11-27T07:57:24.387+0000] {standard_task_runner.py:104} ERROR - Failed to execute job 473 for task extract_kalerkantho ('NoneType' object has no attribute 'find_all'; 56)
[2023-11-27T07:57:24.429+0000] {local_task_job_runner.py:228} INFO - Task exited with return code 1
[2023-11-27T07:57:24.451+0000] {taskinstance.py:2778} INFO - 0 downstream tasks scheduled from follow-on schedule check
