[2023-09-29T22:09:27.779+0000] {taskinstance.py:1157} INFO - Dependencies all met for dep_context=non-requeueable deps ti=<TaskInstance: ETL_Pipeline.load_to_gcp scheduled__2023-09-29T21:00:00+00:00 [queued]>
[2023-09-29T22:09:27.787+0000] {taskinstance.py:1157} INFO - Dependencies all met for dep_context=requeueable deps ti=<TaskInstance: ETL_Pipeline.load_to_gcp scheduled__2023-09-29T21:00:00+00:00 [queued]>
[2023-09-29T22:09:27.788+0000] {taskinstance.py:1359} INFO - Starting attempt 2 of 2
[2023-09-29T22:09:27.800+0000] {taskinstance.py:1380} INFO - Executing <Task(PythonOperator): load_to_gcp> on 2023-09-29 21:00:00+00:00
[2023-09-29T22:09:27.815+0000] {standard_task_runner.py:57} INFO - Started process 1163 to run task
[2023-09-29T22:09:27.820+0000] {standard_task_runner.py:84} INFO - Running: ['***', 'tasks', 'run', 'ETL_Pipeline', 'load_to_gcp', 'scheduled__2023-09-29T21:00:00+00:00', '--job-id', '39', '--raw', '--subdir', 'DAGS_FOLDER/news_aggregator_dag.py', '--cfg-path', '/tmp/tmp432ydf9c']
[2023-09-29T22:09:27.823+0000] {standard_task_runner.py:85} INFO - Job 39: Subtask load_to_gcp
[2023-09-29T22:09:27.862+0000] {task_command.py:415} INFO - Running <TaskInstance: ETL_Pipeline.load_to_gcp scheduled__2023-09-29T21:00:00+00:00 [running]> on host 8b9d74f8b315
[2023-09-29T22:09:27.930+0000] {taskinstance.py:1660} INFO - Exporting env vars: AIRFLOW_CTX_DAG_OWNER='***' AIRFLOW_CTX_DAG_ID='ETL_Pipeline' AIRFLOW_CTX_TASK_ID='load_to_gcp' AIRFLOW_CTX_EXECUTION_DATE='2023-09-29T21:00:00+00:00' AIRFLOW_CTX_TRY_NUMBER='2' AIRFLOW_CTX_DAG_RUN_ID='scheduled__2023-09-29T21:00:00+00:00'
[2023-09-29T22:09:30.935+0000] {_metadata.py:141} WARNING - Compute Engine Metadata server unavailable on attempt 1 of 3. Reason: timed out
[2023-09-29T22:09:33.938+0000] {_metadata.py:141} WARNING - Compute Engine Metadata server unavailable on attempt 2 of 3. Reason: timed out
[2023-09-29T22:09:36.942+0000] {_metadata.py:141} WARNING - Compute Engine Metadata server unavailable on attempt 3 of 3. Reason: timed out
[2023-09-29T22:09:36.943+0000] {_default.py:340} WARNING - Authentication failed using Compute Engine authentication due to unavailable metadata server.
[2023-09-29T22:09:36.944+0000] {taskinstance.py:1935} ERROR - Task failed with exception
Traceback (most recent call last):
  File "/home/airflow/.local/lib/python3.8/site-packages/airflow/operators/python.py", line 192, in execute
    return_value = self.execute_callable()
  File "/home/airflow/.local/lib/python3.8/site-packages/airflow/operators/python.py", line 209, in execute_callable
    return self.python_callable(*self.op_args, **self.op_kwargs)
  File "/opt/airflow/dags/utils/helper.py", line 53, in load_to_gcp
    storage_client = storage.Client(project=GCP_PROJECT_ID)
  File "/home/airflow/.local/lib/python3.8/site-packages/google/cloud/storage/client.py", line 173, in __init__
    super(Client, self).__init__(
  File "/home/airflow/.local/lib/python3.8/site-packages/google/cloud/client/__init__.py", line 321, in __init__
    Client.__init__(
  File "/home/airflow/.local/lib/python3.8/site-packages/google/cloud/client/__init__.py", line 178, in __init__
    credentials, _ = google.auth.default(scopes=scopes)
  File "/home/airflow/.local/lib/python3.8/site-packages/google/auth/_default.py", line 692, in default
    raise exceptions.DefaultCredentialsError(_CLOUD_SDK_MISSING_CREDENTIALS)
google.auth.exceptions.DefaultCredentialsError: Your default credentials were not found. To set up Application Default Credentials, see https://cloud.google.com/docs/authentication/external/set-up-adc for more information.
[2023-09-29T22:09:36.961+0000] {taskinstance.py:1398} INFO - Marking task as FAILED. dag_id=ETL_Pipeline, task_id=load_to_gcp, execution_date=20230929T210000, start_date=20230929T220927, end_date=20230929T220936
[2023-09-29T22:09:36.976+0000] {standard_task_runner.py:104} ERROR - Failed to execute job 39 for task load_to_gcp (Your default credentials were not found. To set up Application Default Credentials, see https://cloud.google.com/docs/authentication/external/set-up-adc for more information.; 1163)
[2023-09-29T22:09:37.021+0000] {local_task_job_runner.py:228} INFO - Task exited with return code 1
[2023-09-29T22:09:37.047+0000] {taskinstance.py:2776} INFO - 0 downstream tasks scheduled from follow-on schedule check
[2023-09-29T22:18:18.300+0000] {taskinstance.py:1157} INFO - Dependencies all met for dep_context=non-requeueable deps ti=<TaskInstance: ETL_Pipeline.load_to_gcp scheduled__2023-09-29T21:00:00+00:00 [queued]>
[2023-09-29T22:18:18.310+0000] {taskinstance.py:1157} INFO - Dependencies all met for dep_context=requeueable deps ti=<TaskInstance: ETL_Pipeline.load_to_gcp scheduled__2023-09-29T21:00:00+00:00 [queued]>
[2023-09-29T22:18:18.311+0000] {taskinstance.py:1359} INFO - Starting attempt 2 of 2
[2023-09-29T22:18:18.325+0000] {taskinstance.py:1380} INFO - Executing <Task(PythonOperator): load_to_gcp> on 2023-09-29 21:00:00+00:00
[2023-09-29T22:18:18.330+0000] {standard_task_runner.py:57} INFO - Started process 51 to run task
[2023-09-29T22:18:18.333+0000] {standard_task_runner.py:84} INFO - Running: ['***', 'tasks', 'run', 'ETL_Pipeline', 'load_to_gcp', 'scheduled__2023-09-29T21:00:00+00:00', '--job-id', '49', '--raw', '--subdir', 'DAGS_FOLDER/news_aggregator_dag.py', '--cfg-path', '/tmp/tmpk_8dcel7']
[2023-09-29T22:18:18.335+0000] {standard_task_runner.py:85} INFO - Job 49: Subtask load_to_gcp
[2023-09-29T22:18:18.371+0000] {task_command.py:415} INFO - Running <TaskInstance: ETL_Pipeline.load_to_gcp scheduled__2023-09-29T21:00:00+00:00 [running]> on host eb2de9d03ecb
[2023-09-29T22:18:18.431+0000] {taskinstance.py:1660} INFO - Exporting env vars: AIRFLOW_CTX_DAG_OWNER='***' AIRFLOW_CTX_DAG_ID='ETL_Pipeline' AIRFLOW_CTX_TASK_ID='load_to_gcp' AIRFLOW_CTX_EXECUTION_DATE='2023-09-29T21:00:00+00:00' AIRFLOW_CTX_TRY_NUMBER='2' AIRFLOW_CTX_DAG_RUN_ID='scheduled__2023-09-29T21:00:00+00:00'
[2023-09-29T22:18:21.442+0000] {_metadata.py:141} WARNING - Compute Engine Metadata server unavailable on attempt 1 of 3. Reason: timed out
[2023-09-29T22:18:24.446+0000] {_metadata.py:141} WARNING - Compute Engine Metadata server unavailable on attempt 2 of 3. Reason: timed out
[2023-09-29T22:18:27.451+0000] {_metadata.py:141} WARNING - Compute Engine Metadata server unavailable on attempt 3 of 3. Reason: timed out
[2023-09-29T22:18:27.451+0000] {_default.py:340} WARNING - Authentication failed using Compute Engine authentication due to unavailable metadata server.
[2023-09-29T22:18:27.451+0000] {taskinstance.py:1935} ERROR - Task failed with exception
Traceback (most recent call last):
  File "/home/airflow/.local/lib/python3.8/site-packages/airflow/operators/python.py", line 192, in execute
    return_value = self.execute_callable()
  File "/home/airflow/.local/lib/python3.8/site-packages/airflow/operators/python.py", line 209, in execute_callable
    return self.python_callable(*self.op_args, **self.op_kwargs)
  File "/opt/airflow/dags/utils/helper.py", line 53, in load_to_gcp
    storage_client = storage.Client(project=GCP_PROJECT_ID)
  File "/home/airflow/.local/lib/python3.8/site-packages/google/cloud/storage/client.py", line 173, in __init__
    super(Client, self).__init__(
  File "/home/airflow/.local/lib/python3.8/site-packages/google/cloud/client/__init__.py", line 321, in __init__
    Client.__init__(
  File "/home/airflow/.local/lib/python3.8/site-packages/google/cloud/client/__init__.py", line 178, in __init__
    credentials, _ = google.auth.default(scopes=scopes)
  File "/home/airflow/.local/lib/python3.8/site-packages/google/auth/_default.py", line 692, in default
    raise exceptions.DefaultCredentialsError(_CLOUD_SDK_MISSING_CREDENTIALS)
google.auth.exceptions.DefaultCredentialsError: Your default credentials were not found. To set up Application Default Credentials, see https://cloud.google.com/docs/authentication/external/set-up-adc for more information.
[2023-09-29T22:18:27.459+0000] {taskinstance.py:1398} INFO - Marking task as FAILED. dag_id=ETL_Pipeline, task_id=load_to_gcp, execution_date=20230929T210000, start_date=20230929T221818, end_date=20230929T221827
[2023-09-29T22:18:27.473+0000] {standard_task_runner.py:104} ERROR - Failed to execute job 49 for task load_to_gcp (Your default credentials were not found. To set up Application Default Credentials, see https://cloud.google.com/docs/authentication/external/set-up-adc for more information.; 51)
[2023-09-29T22:18:27.487+0000] {local_task_job_runner.py:228} INFO - Task exited with return code 1
[2023-09-29T22:18:27.497+0000] {taskinstance.py:2776} INFO - 0 downstream tasks scheduled from follow-on schedule check
