[2023-11-30T00:25:20.170+0000] {taskinstance.py:1159} INFO - Dependencies all met for dep_context=non-requeueable deps ti=<TaskInstance: ETL_Pipeline.extract_kalerkantho scheduled__2023-11-29T00:00:00+00:00 [queued]>
[2023-11-30T00:25:20.178+0000] {taskinstance.py:1159} INFO - Dependencies all met for dep_context=requeueable deps ti=<TaskInstance: ETL_Pipeline.extract_kalerkantho scheduled__2023-11-29T00:00:00+00:00 [queued]>
[2023-11-30T00:25:20.179+0000] {taskinstance.py:1361} INFO - Starting attempt 1 of 2
[2023-11-30T00:25:20.192+0000] {taskinstance.py:1382} INFO - Executing <Task(PythonOperator): extract_kalerkantho> on 2023-11-29 00:00:00+00:00
[2023-11-30T00:25:20.199+0000] {standard_task_runner.py:57} INFO - Started process 11043 to run task
[2023-11-30T00:25:20.202+0000] {standard_task_runner.py:84} INFO - Running: ['***', 'tasks', 'run', 'ETL_Pipeline', 'extract_kalerkantho', 'scheduled__2023-11-29T00:00:00+00:00', '--job-id', '537', '--raw', '--subdir', 'DAGS_FOLDER/ETL_Pipeline.py', '--cfg-path', '/tmp/tmp_2062elj']
[2023-11-30T00:25:20.205+0000] {standard_task_runner.py:85} INFO - Job 537: Subtask extract_kalerkantho
[2023-11-30T00:25:20.242+0000] {task_command.py:416} INFO - Running <TaskInstance: ETL_Pipeline.extract_kalerkantho scheduled__2023-11-29T00:00:00+00:00 [running]> on host 4012deabc79b
[2023-11-30T00:25:20.327+0000] {taskinstance.py:1662} INFO - Exporting env vars: AIRFLOW_CTX_DAG_OWNER='***' AIRFLOW_CTX_DAG_ID='ETL_Pipeline' AIRFLOW_CTX_TASK_ID='extract_kalerkantho' AIRFLOW_CTX_EXECUTION_DATE='2023-11-29T00:00:00+00:00' AIRFLOW_CTX_TRY_NUMBER='1' AIRFLOW_CTX_DAG_RUN_ID='scheduled__2023-11-29T00:00:00+00:00'
[2023-11-30T00:25:20.368+0000] {extract.py:22} ERROR - Could not fetch content due to error: HTTPSConnectionPool(host='www.kalerkantho.com', port=443): Max retries exceeded with url: /sitemap.xml (Caused by NewConnectionError('<urllib3.connection.HTTPSConnection object at 0x7f1340546550>: Failed to establish a new connection: [Errno -3] Temporary failure in name resolution'))
[2023-11-30T00:25:20.368+0000] {taskinstance.py:1937} ERROR - Task failed with exception
Traceback (most recent call last):
  File "/home/airflow/.local/lib/python3.8/site-packages/airflow/operators/python.py", line 192, in execute
    return_value = self.execute_callable()
  File "/home/airflow/.local/lib/python3.8/site-packages/airflow/operators/python.py", line 209, in execute_callable
    return self.python_callable(*self.op_args, **self.op_kwargs)
  File "/opt/airflow/dags/utils/extract.py", line 52, in parse_from_kalerkantho
    latest_news_sitemap = sitemap_soup.find_all("loc")[1].text
AttributeError: 'NoneType' object has no attribute 'find_all'
[2023-11-30T00:25:20.377+0000] {taskinstance.py:1400} INFO - Marking task as UP_FOR_RETRY. dag_id=ETL_Pipeline, task_id=extract_kalerkantho, execution_date=20231129T000000, start_date=20231130T002520, end_date=20231130T002520
[2023-11-30T00:25:20.391+0000] {standard_task_runner.py:104} ERROR - Failed to execute job 537 for task extract_kalerkantho ('NoneType' object has no attribute 'find_all'; 11043)
[2023-11-30T00:25:20.415+0000] {local_task_job_runner.py:228} INFO - Task exited with return code 1
[2023-11-30T00:25:20.456+0000] {taskinstance.py:2778} INFO - 0 downstream tasks scheduled from follow-on schedule check
