[2023-11-25T23:11:14.811+0000] {taskinstance.py:1159} INFO - Dependencies all met for dep_context=non-requeueable deps ti=<TaskInstance: ETL_Pipeline.load_to_gcp scheduled__2023-11-25T21:00:00+00:00 [queued]>
[2023-11-25T23:11:14.817+0000] {taskinstance.py:1159} INFO - Dependencies all met for dep_context=requeueable deps ti=<TaskInstance: ETL_Pipeline.load_to_gcp scheduled__2023-11-25T21:00:00+00:00 [queued]>
[2023-11-25T23:11:14.818+0000] {taskinstance.py:1361} INFO - Starting attempt 2 of 2
[2023-11-25T23:11:14.828+0000] {taskinstance.py:1382} INFO - Executing <Task(PythonOperator): load_to_gcp> on 2023-11-25 21:00:00+00:00
[2023-11-25T23:11:14.833+0000] {standard_task_runner.py:57} INFO - Started process 2261 to run task
[2023-11-25T23:11:14.835+0000] {standard_task_runner.py:84} INFO - Running: ['***', 'tasks', 'run', 'ETL_Pipeline', 'load_to_gcp', 'scheduled__2023-11-25T21:00:00+00:00', '--job-id', '437', '--raw', '--subdir', 'DAGS_FOLDER/ETL_Pipeline.py', '--cfg-path', '/tmp/tmpq78s7o9l']
[2023-11-25T23:11:14.837+0000] {standard_task_runner.py:85} INFO - Job 437: Subtask load_to_gcp
[2023-11-25T23:11:14.870+0000] {task_command.py:416} INFO - Running <TaskInstance: ETL_Pipeline.load_to_gcp scheduled__2023-11-25T21:00:00+00:00 [running]> on host 4012deabc79b
[2023-11-25T23:11:14.922+0000] {taskinstance.py:1662} INFO - Exporting env vars: AIRFLOW_CTX_DAG_OWNER='***' AIRFLOW_CTX_DAG_ID='ETL_Pipeline' AIRFLOW_CTX_TASK_ID='load_to_gcp' AIRFLOW_CTX_EXECUTION_DATE='2023-11-25T21:00:00+00:00' AIRFLOW_CTX_TRY_NUMBER='2' AIRFLOW_CTX_DAG_RUN_ID='scheduled__2023-11-25T21:00:00+00:00'
[2023-11-25T23:11:14.961+0000] {taskinstance.py:1937} ERROR - Task failed with exception
Traceback (most recent call last):
  File "/home/airflow/.local/lib/python3.8/site-packages/airflow/operators/python.py", line 192, in execute
    return_value = self.execute_callable()
  File "/home/airflow/.local/lib/python3.8/site-packages/airflow/operators/python.py", line 209, in execute_callable
    return self.python_callable(*self.op_args, **self.op_kwargs)
  File "/opt/airflow/dags/utils/helper.py", line 74, in load_to_gcp
    blob.upload_from_filename(local_file_path)
  File "/home/airflow/.local/lib/python3.8/site-packages/google/cloud/storage/blob.py", line 2926, in upload_from_filename
    self._handle_filename_and_upload(
  File "/home/airflow/.local/lib/python3.8/site-packages/google/cloud/storage/blob.py", line 2794, in _handle_filename_and_upload
    with open(filename, "rb") as file_obj:
FileNotFoundError: [Errno 2] No such file or directory: 'dags/data/scraped_data_2023-11-25.csv'
[2023-11-25T23:11:14.967+0000] {taskinstance.py:1400} INFO - Marking task as FAILED. dag_id=ETL_Pipeline, task_id=load_to_gcp, execution_date=20231125T210000, start_date=20231125T231114, end_date=20231125T231114
[2023-11-25T23:11:14.977+0000] {standard_task_runner.py:104} ERROR - Failed to execute job 437 for task load_to_gcp ([Errno 2] No such file or directory: 'dags/data/scraped_data_2023-11-25.csv'; 2261)
[2023-11-25T23:11:15.007+0000] {local_task_job_runner.py:228} INFO - Task exited with return code 1
[2023-11-25T23:11:15.023+0000] {taskinstance.py:2778} INFO - 0 downstream tasks scheduled from follow-on schedule check
