[2023-12-07T10:30:46.559+0000] {taskinstance.py:1159} INFO - Dependencies all met for dep_context=non-requeueable deps ti=<TaskInstance: ETL_Pipeline.extract_kalerkantho scheduled__2023-12-06T00:00:00+00:00 [queued]>
[2023-12-07T10:30:46.576+0000] {taskinstance.py:1159} INFO - Dependencies all met for dep_context=requeueable deps ti=<TaskInstance: ETL_Pipeline.extract_kalerkantho scheduled__2023-12-06T00:00:00+00:00 [queued]>
[2023-12-07T10:30:46.577+0000] {taskinstance.py:1361} INFO - Starting attempt 1 of 2
[2023-12-07T10:30:46.607+0000] {taskinstance.py:1382} INFO - Executing <Task(PythonOperator): extract_kalerkantho> on 2023-12-06 00:00:00+00:00
[2023-12-07T10:30:46.630+0000] {standard_task_runner.py:57} INFO - Started process 10588 to run task
[2023-12-07T10:30:46.636+0000] {standard_task_runner.py:84} INFO - Running: ['***', 'tasks', 'run', 'ETL_Pipeline', 'extract_kalerkantho', 'scheduled__2023-12-06T00:00:00+00:00', '--job-id', '588', '--raw', '--subdir', 'DAGS_FOLDER/ETL_Pipeline.py', '--cfg-path', '/tmp/tmprbcje8ap']
[2023-12-07T10:30:46.640+0000] {standard_task_runner.py:85} INFO - Job 588: Subtask extract_kalerkantho
[2023-12-07T10:30:46.759+0000] {task_command.py:416} INFO - Running <TaskInstance: ETL_Pipeline.extract_kalerkantho scheduled__2023-12-06T00:00:00+00:00 [running]> on host 4012deabc79b
[2023-12-07T10:30:46.876+0000] {taskinstance.py:1662} INFO - Exporting env vars: AIRFLOW_CTX_DAG_OWNER='***' AIRFLOW_CTX_DAG_ID='ETL_Pipeline' AIRFLOW_CTX_TASK_ID='extract_kalerkantho' AIRFLOW_CTX_EXECUTION_DATE='2023-12-06T00:00:00+00:00' AIRFLOW_CTX_TRY_NUMBER='1' AIRFLOW_CTX_DAG_RUN_ID='scheduled__2023-12-06T00:00:00+00:00'
[2023-12-07T10:30:46.881+0000] {extract.py:22} ERROR - Could not fetch content due to error: HTTPSConnectionPool(host='www.kalerkantho.com', port=443): Max retries exceeded with url: /sitemap.xml (Caused by NewConnectionError('<urllib3.connection.HTTPSConnection object at 0x7fe3c0a77a60>: Failed to establish a new connection: [Errno -3] Temporary failure in name resolution'))
[2023-12-07T10:30:46.881+0000] {taskinstance.py:1937} ERROR - Task failed with exception
Traceback (most recent call last):
  File "/home/airflow/.local/lib/python3.8/site-packages/airflow/operators/python.py", line 192, in execute
    return_value = self.execute_callable()
  File "/home/airflow/.local/lib/python3.8/site-packages/airflow/operators/python.py", line 209, in execute_callable
    return self.python_callable(*self.op_args, **self.op_kwargs)
  File "/opt/airflow/dags/utils/extract.py", line 52, in parse_from_kalerkantho
    latest_news_sitemap = sitemap_soup.find_all("loc")[1].text
AttributeError: 'NoneType' object has no attribute 'find_all'
[2023-12-07T10:30:46.889+0000] {taskinstance.py:1400} INFO - Marking task as UP_FOR_RETRY. dag_id=ETL_Pipeline, task_id=extract_kalerkantho, execution_date=20231206T000000, start_date=20231207T103046, end_date=20231207T103046
[2023-12-07T10:30:46.906+0000] {standard_task_runner.py:104} ERROR - Failed to execute job 588 for task extract_kalerkantho ('NoneType' object has no attribute 'find_all'; 10588)
[2023-12-07T10:30:46.937+0000] {local_task_job_runner.py:228} INFO - Task exited with return code 1
[2023-12-07T10:30:46.970+0000] {taskinstance.py:2778} INFO - 0 downstream tasks scheduled from follow-on schedule check
