[2023-08-05T06:00:03.328+0000] {taskinstance.py:1103} INFO - Dependencies all met for dep_context=non-requeueable deps ti=<TaskInstance: ETL_Pipeline.transform_data scheduled__2023-08-05T05:00:00+00:00 [queued]>
[2023-08-05T06:00:03.341+0000] {taskinstance.py:1103} INFO - Dependencies all met for dep_context=requeueable deps ti=<TaskInstance: ETL_Pipeline.transform_data scheduled__2023-08-05T05:00:00+00:00 [queued]>
[2023-08-05T06:00:03.341+0000] {taskinstance.py:1308} INFO - Starting attempt 1 of 2
[2023-08-05T06:00:03.358+0000] {taskinstance.py:1327} INFO - Executing <Task(PythonOperator): transform_data> on 2023-08-05 05:00:00+00:00
[2023-08-05T06:00:03.365+0000] {standard_task_runner.py:57} INFO - Started process 321 to run task
[2023-08-05T06:00:03.368+0000] {standard_task_runner.py:84} INFO - Running: ['***', 'tasks', 'run', 'ETL_Pipeline', 'transform_data', 'scheduled__2023-08-05T05:00:00+00:00', '--job-id', '4891', '--raw', '--subdir', 'DAGS_FOLDER/my_first_dag.py', '--cfg-path', '/tmp/tmpvq21ydsa']
[2023-08-05T06:00:03.371+0000] {standard_task_runner.py:85} INFO - Job 4891: Subtask transform_data
[2023-08-05T06:00:03.452+0000] {task_command.py:410} INFO - Running <TaskInstance: ETL_Pipeline.transform_data scheduled__2023-08-05T05:00:00+00:00 [running]> on host 794dc2638f7c
[2023-08-05T06:00:03.564+0000] {taskinstance.py:1547} INFO - Exporting env vars: AIRFLOW_CTX_DAG_OWNER='***' AIRFLOW_CTX_DAG_ID='ETL_Pipeline' AIRFLOW_CTX_TASK_ID='transform_data' AIRFLOW_CTX_EXECUTION_DATE='2023-08-05T05:00:00+00:00' AIRFLOW_CTX_TRY_NUMBER='1' AIRFLOW_CTX_DAG_RUN_ID='scheduled__2023-08-05T05:00:00+00:00'
[2023-08-05T06:00:03.570+0000] {logging_mixin.py:150} WARNING - Scraping Progress:   0%|          | 0/10 [00:00<?, ?it/s]
[2023-08-05T06:00:03.574+0000] {logging_mixin.py:150} WARNING - Scraping Progress:   0%|          | 0/10 [00:00<?, ?it/s]
[2023-08-05T06:00:03.574+0000] {taskinstance.py:1824} ERROR - Task failed with exception
Traceback (most recent call last):
  File "/home/airflow/.local/lib/python3.7/site-packages/airflow/operators/python.py", line 181, in execute
    return_value = self.execute_callable()
  File "/home/airflow/.local/lib/python3.7/site-packages/airflow/operators/python.py", line 198, in execute_callable
    return self.python_callable(*self.op_args, **self.op_kwargs)
  File "/opt/airflow/dags/my_first_dag.py", line 40, in transform_data
    data_list.append(scrape_data_from_url(url))
  File "/opt/airflow/dags/utils/scraper.py", line 8, in scrape_data_from_url
    article.parse()
  File "/home/airflow/.local/lib/python3.7/site-packages/newspaper/article.py", line 191, in parse
    self.throw_if_not_downloaded_verbose()
  File "/home/airflow/.local/lib/python3.7/site-packages/newspaper/article.py", line 532, in throw_if_not_downloaded_verbose
    (self.download_exception_msg, self.url))
newspaper.article.ArticleException: Article `download()` failed with HTTPSConnectionPool(host='www.prothomalo.com', port=443): Max retries exceeded with url: /business/egkvb1ptqt (Caused by NewConnectionError('<urllib3.connection.HTTPSConnection object at 0x7f90b8315190>: Failed to establish a new connection: [Errno -3] Temporary failure in name resolution')) on URL https://www.prothomalo.com/business/egkvb1ptqt
[2023-08-05T06:00:03.582+0000] {taskinstance.py:1350} INFO - Marking task as UP_FOR_RETRY. dag_id=ETL_Pipeline, task_id=transform_data, execution_date=20230805T050000, start_date=20230805T060003, end_date=20230805T060003
[2023-08-05T06:00:03.594+0000] {standard_task_runner.py:109} ERROR - Failed to execute job 4891 for task transform_data (Article `download()` failed with HTTPSConnectionPool(host='www.prothomalo.com', port=443): Max retries exceeded with url: /business/egkvb1ptqt (Caused by NewConnectionError('<urllib3.connection.HTTPSConnection object at 0x7f90b8315190>: Failed to establish a new connection: [Errno -3] Temporary failure in name resolution')) on URL https://www.prothomalo.com/business/egkvb1ptqt; 321)
[2023-08-05T06:00:03.619+0000] {local_task_job_runner.py:225} INFO - Task exited with return code 1
[2023-08-05T06:00:03.651+0000] {taskinstance.py:2653} INFO - 0 downstream tasks scheduled from follow-on schedule check
